I'm sorry, but an uncaught exception occurred.

While running game code:
  File "game/script.rpy", line 1185, in script
    v "I think we’ll remember all of this important information for a long time."
Exception: Sayer 'v' is not defined.

-- Full Traceback ------------------------------------------------------------

Full traceback:
  File "game/script.rpy", line 1185, in script
    v "I think we’ll remember all of this important information for a long time."
  File "renpy/ast.py", line 671, in execute
    who = eval_who(self.who, self.who_fast)
  File "renpy/ast.py", line 574, in eval_who
    raise Exception("Sayer '%s' is not defined." % who)
Exception: Sayer 'v' is not defined.

